Workbook
Name Slicer_Account_Manager: #N/A
Name Slicer_Region: #N/A

Sheet Summary
B2: RECEIVABLE SUMMARY(In $)
B3: Sum of USD AMOUNT | C3: Column Labels
B4: Row Labels | C4: 0-30 days | D4: 31-60 days | E4: 61-90 days | F4: Over 90+ days | G4: Grand Total
B5: EU/UK | C5: 36034.993 | D5: 4096.0347 | E5: 4162.1359 | F5: 4250.9684 | G5: 48544.132
B6: APAC | C6: 304837.31 | D6: 40947.48 | E6: 65412.636 | F6: 51245.138 | G6: 462442.56
B7: Shared Center | C7: 35014.798 | D7: 23869.362 | E7: 8504.5 | F7: 78993.5 | G7: 146382.16
B8: Americas | C8: 201735.55 | D8: 21503.113 | E8: 168.33774 | F8: 18888.387 | G8: 242295.38
B9: MEA | C9: 61256.36 | D9: 8122.75 | E9: 7766.25 | F9: 12745.24 | G9: 89890.6
B10: Grand Total | C10: 638879.01 | D10: 98538.739 | E10: 86013.86 | F10: 166123.23 | G10: 989554.84
B13: Regional Outstanding (In $)
B14: Region | C14: 0-30 days | D14: 31-60 days | E14: 61-90 days | F14: Over 90+ days | G14: Grand Total | H14: Region-wise contribution(%)
B15: EU/UK | C15: =GETPIVOTDATA("USD AMOUNT",$B$3,"Region","EU/UK","Ageing Tier","0-30 days") -> 36034.993 | D15: =GETPIVOTDATA("USD AMOUNT",$B$3,"Region","EU/UK","Ageing Tier","31-60 days") -> 4096.0347 | E15: =GETPIVOTDATA("USD AMOUNT",$B$3,"Region","EU/UK","Ageing Tier","61-90 days") -> 4162.1359 | F15: =GETPIVOTDATA("USD AMOUNT",$B$3,"Region","EU/UK","Ageing Tier","Over 90+ days") -> 4250.9684 | G15: =SUM(C15:F15) -> 48544.132 | H15: =G15/G20 -> 0.049056535
B16: Americas | C16: =GETPIVOTDATA("USD AMOUNT",$B$3,"Region","Americas","Ageing Tier","0-30 days") -> 201735.55 | D16: =GETPIVOTDATA("USD AMOUNT",$B$3,"Region","Americas","Ageing Tier","31-60 days") -> 21503.113 | E16: =GETPIVOTDATA("USD AMOUNT",$B$3,"Region","Americas","Ageing Tier","61-90 days") -> 168.33774 | F16: =GETPIVOTDATA("USD AMOUNT",$B$3,"Region","Americas","Ageing Tier","Over 90+ days") -> 18888.387 | G16: =SUM(C16:F16) -> 242295.38 | H16: =G16/G20 -> 0.24485291
B17: MEA | C17: =GETPIVOTDATA("USD AMOUNT",$B$3,"Region","MEA","Ageing Tier","0-30 days") -> 61256.36 | D17: =GETPIVOTDATA("USD AMOUNT",$B$3,"Region","MEA","Ageing Tier","31-60 days") -> 8122.75 | E17: =GETPIVOTDATA("USD AMOUNT",$B$3,"Region","MEA","Ageing Tier","61-90 days") -> 7766.25 | F17: =GETPIVOTDATA("USD AMOUNT",$B$3,"Region","MEA","Ageing Tier","Over 90+ days") -> 12745.24 | G17: =SUM(C17:F17) -> 89890.6 | H17: =G17/G20 -> 0.090839432
B18: APAC | C18: =GETPIVOTDATA("USD AMOUNT",$B$3,"Region","APAC","Ageing Tier","0-30 days") -> 304837.31 | D18: =GETPIVOTDATA("USD AMOUNT",$B$3,"Region","APAC","Ageing Tier","31-60 days") -> 40947.48 | E18: =GETPIVOTDATA("USD AMOUNT",$B$3,"Region","APAC","Ageing Tier","61-90 days") -> 65412.636 | F18: =GETPIVOTDATA("USD AMOUNT",$B$3,"Region","APAC","Ageing Tier","Over 90+ days") -> 51245.138 | G18: =SUM(C18:F18) -> 462442.56 | H18: =G18/G20 -> 0.46732384
B19: Shared Centre | C19: =GETPIVOTDATA("USD AMOUNT",$B$3,"Region","Shared Center","Ageing Tier","0-30 days") -> 35014.798 | D19: =GETPIVOTDATA("USD AMOUNT",$B$3,"Region","Shared Center","Ageing Tier","31-60 days") -> 23869.362 | E19: =GETPIVOTDATA("USD AMOUNT",$B$3,"Region","Shared Center","Ageing Tier","61-90 days") -> 8504.5 | F19: =GETPIVOTDATA("USD AMOUNT",$B$3,"Region","Shared Center","Ageing Tier","Over 90+ days") -> 78993.5 | G19: =SUM(C19:F19) -> 146382.16 | H19: =G19/G20 -> 0.14792728
B20: Grand Total | C20: =SUM(C15:C19) -> 638879.01 | D20: =SUM(D15:D19) -> 98538.739 | E20: =SUM(E15:E19) -> 86013.86 | F20: =SUM(F15:F19) -> 166123.23 | G20: =SUM(C20:F20) -> 989554.84 | H20: 1
B21: Ageing-wise contribution(%) | C21: =C20/G20 -> 0.64562264 | D21: =D20/G20 -> 0.099578856 | E21: =E20/G20 -> 0.086921772 | F21: =F20/G20 -> 0.16787673 | G21: 1
B23: Customer Label | C23: Account Manager | D23: BD | E23: Amount($)
B24: Al Muzaini Exchange | C24: Jerome Coelho | D24: Ashraf Omran | E24: -48
B25: Aspire FT Pte Ltd | C25: Shi Yin | D25: Gitesh Athavale | E25: -1826.2714
B26: Loadpass LTDA | C26: Eduardo Avallone | D26: Christina Hutchinson | E26: -152.91
B27: borderless llc | C27: Lia Susin | D27: NA | E27: -3310.7
B28: Grand Total | E28: -5337.8814
B33: Client Name | C33: AM/BD | D33: Amount ($)
B34: Al Muzaini Exchange | C34: Ashraf Omran | D34: -48
B35: Loadpass LTDA | C35: Eduardo Avallone | D35: -152.91
B36: Aspire FT Pte Ltd | C36: Shi Yin | D36: -1826.2714
B37: borderless llc | C37: Lia Susin | D37: -3310.7
C38: Total | D38: =SUM(D34:D37) -> -5337.8814

Sheet Governance
A3: Sum of USD AMOUNT | J3: Month
A4: Client Name | B4: Region | C4: Platform | D4: Settlement Type | E4: Client Status | F4: AR's Comments | G4: Account Manager | H4: BD | I4: Year | J4: Jan | K4: Feb | L4: Mar | M4: Apr | N4: Sep | O4: Oct | P4: Nov | Q4: Dec | R4: Jul | S4: Aug | T4: Grand Total
A5: Loadpass LTDA | B5: USA | C5: N1 | D5: Bank Transfer | E5: Active | F5: AM is chasing the client to clear all o/s invoices | G5: Lia Susin | H5: Christina Hutchinson | I5: 2025 | N5: 3487.5 | O5: 2602.25 | P5: 1786.14 | Q5: 1659.62 | R5: 3495.5 | S5: 3485 | T5: 16516.01
A6: Loadpass LTDA | B6: USA | C6: N1 | D6: Bank Transfer | E6: Active | F6: AM is chasing the client to clear all o/s invoices | G6: Lia Susin | H6: Christina Hutchinson | I6: 2026 | K6: 608.97 | T6: 608.97
A7: KOHO Financial Inc.-Verify | B7: USA | C7: N1 | D7: Bank Transfer | E7: Active | F7: No response from the client post reminder sent | G7: Tanu Arora | H7: Vinoth M | I7: 2026 | M7: 312 | T7: 312
A8: MyBeacon Services Inc. | B8: USA | C8: N1 | D8: Bank Transfer | E8: Active | F8: No response from the client post reminder sent | G8: Tanu Arora | H8: Michael Bermingham | I8: 2026 | J8: 265.36476 | K8: 1020.4297 | L8: 5219.9482 | M8: 39.566801 | T8: 6545.3094
A9: MyBeacon Services Inc.-Verify | B9: USA | C9: N1 | D9: Bank Transfer | E9: Active | F9: No response from the client post reminder sent | G9: Tanu Arora | H9: Michael Bermingham | I9: 2026 | J9: 36.32 | K9: 43.5 | L9: 7.5 | T9: 87.32
A10: KOHO Financial Inc. | B10: USA | C10: N1 | D10: Bank Transfer | E10: Active | F10: No response from the client post reminder sent | G10: Tanu Arora | H10: Vinoth M | I10: 2026 | M10: 1412.24 | T10: 1412.24
A11: BEXS BANCO DE CAMBIO S.A. | B11: USA | C11: Masspay | D11: Bank Transfer | E11: Active | F11: No response from the client post reminder sent | G11: Eduardo Avallone | H11: Christina Hutchinson | I11: 2026 | M11: 500 | T11: 500
A12: Poaster Technologies Inc. DBA Warp | B12: USA | C12: N1 | D12: Bank Transfer | E12: Active | F12: No response from the client post reminder sent | G12: Tulio Lima | H12: NA | I12: 2026 | L12: 250 | M12: 130 | T12: 380
A13: Grand Total | J13: 301.68476 | K13: 1672.8997 | L13: 5477.4482 | M13: 2393.8068 | N13: 3487.5 | O13: 2602.25 | P13: 1786.14 | Q13: 1659.62 | R13: 3495.5 | S13: 3485 | T13: 26361.849

Sheet Sheet1
A1: Region | B1: APAC/ME
A2: Account Manager | B2: Hui Ting Hoe
A4: Sum of USD AMOUNT | B4: Column Labels
A5: Row Labels | B5: 0-30 days | C5: 31-60 days | D5: 61-90 days | E5: Over 90+ days | F5: Grand Total
A6: Hong Leong Finance Limited | B6: 8074.9534 | D6: 4652.5833 | F6: 12727.537
A7: iFast Financial Pte Ltd | B7: 3452.8545 | F7: 3452.8545
A8: Transwap Private Limited | B8: 4406.6802 | C8: 3236.5106 | D8: 3389.1551 | E8: 23791.203 | F8: 34823.549
A9: Grand Total | B9: 15934.488 | C9: 3236.5106 | D9: 8041.7385 | E9: 23791.203 | F9: 51003.94

Sheet Invoices
A1: Platform | B1: Customer Label | C1: Region | D1: Account Manager | E1: BD | F1: Client Status | G1: Year | H1: Settlement Type | I1: Currency | J1: USD AMOUNT | K1: Invoice Amount | L1: Billing Period | M1: Month | N1: Days | O1: Ageing Tier | P1: Fee Type | Q1: Invoice Date | R1: Due Date | S1: Invoice Status | T1: Invoice Number | U1: Reminder Sent | V1: LOD | W1: AR's Comments | X1: AM's Comments | Y1: =TODAY() -> 46232
A2: N1 | B2: SWiM Pay Pty Ltd | C2: =VLOOKUP(B2,Validation!A:B,2,0) -> Shared Center | D2: =VLOOKUP(B2,Validation!A:D,4,0) -> Simrn | E2: =VLOOKUP(B2,Validation!A:E,5,0) -> Vinoth M | F2: Active | G2: =YEAR(L2) -> 2024 | H2: Bank Transfer | I2: USD | J2: =VLOOKUP(I2,'XE rates'!A:D,4,0)*K2 -> 5500 | K2: 5500 | L2: 45597 | M2: =TEXT(L2,"mmm") -> Nov | N2: =$Y$1-R2 -> 595 | O2: =IF(N2<=30, "0-30 days", IF(N2<=60, "31-60 days", IF(N2<=90, "61-90 days", "Over 90+ days"))) -> Over 90+ days | P2: Monthly Billing | Q2: 45597 | R2: 45637 | S2: Outstanding | T2: INV-041224105640 | U2: Yes | V2: Yes | W2: A Letter of Demand (LOD) has been issued, and the account has been suspended. BD has asked client to make partial payment of $25k, awaiting further update. | Y2: =VLOOKUP(T2,'[1]Query result'!$J:$K,2,0) -> 45637 | Z2: =VLOOKUP(T2,'[1]Query result'!$J:$W,14,0) -> 0 | AA2: =K2-Z2 -> 5500
A3: N1 | B3: SWiM Pay Pty Ltd | C3: =VLOOKUP(B3,Validation!A:B,2,0) -> Shared Center | D3: =VLOOKUP(B3,Validation!A:D,4,0) -> Simrn | E3: =VLOOKUP(B3,Validation!A:E,5,0) -> Vinoth M | F3: Active | G3: =YEAR(L3) -> 2025 | H3: Bank Transfer | I3: USD | J3: =VLOOKUP(I3,'XE rates'!A:D,4,0)*K3 -> 9930 | K3: 9930 | L3: 45658 | M3: =TEXT(L3,"mmm") -> Jan | N3: =$Y$1-R3 -> 532 | O3: =IF(N3<=30, "0-30 days", IF(N3<=60, "31-60 days", IF(N3<=90, "61-90 days", "Over 90+ days"))) -> Over 90+ days | P3: Monthly Billing | Q3: 45693 | R3: 45700 | S3: Outstanding | T3: INV-050225183406 | U3: Yes | V3: Yes | W3: A Letter of Demand (LOD) has been issued, and the account has been suspended. BD has asked client to make partial payment of $25k, awaiting further update. | Y3: =VLOOKUP(T3,'[1]Query result'!$J:$K,2,0) -> 45700 | Z3: =VLOOKUP(T3,'[1]Query result'!$J:$W,14,0) -> 0 | AA3: =K3-Z3 -> 9930
A4: N1 | B4: SWiM Pay Pty Ltd | C4: =VLOOKUP(B4,Validation!A:B,2,0) -> Shared Center | D4: =VLOOKUP(B4,Validation!A:D,4,0) -> Simrn | E4: =VLOOKUP(B4,Validation!A:E,5,0) -> Vinoth M | F4: Active | G4: =YEAR(L4) -> 2025 | H4: Bank Transfer | I4: USD | J4: =VLOOKUP(I4,'XE rates'!A:D,4,0)*K4 -> 10000 | K4: 10000 | L4: 45689 | M4: =TEXT(L4,"mmm") -> Feb | N4: =$Y$1-R4 -> 504 | O4: =IF(N4<=30, "0-30 days", IF(N4<=60, "31-60 days", IF(N4<=90, "61-90 days", "Over 90+ days"))) -> Over 90+ days | P4: Monthly Billing | Q4: 45721 | R4: 45728 | S4: Outstanding | T4: INV-050325103203 | U4: Yes | V4: Yes | W4: A Letter of Demand (LOD) has been issued, and the account has been suspended. BD has asked client to make partial payment of $25k, awaiting further update. | Y4: =VLOOKUP(T4,'[1]Query result'!$J:$K,2,0) -> 45728 | Z4: =VLOOKUP(T4,'[1]Query result'!$J:$W,14,0) -> 0 | AA4: =K4-Z4 -> 10000
A5: N1 | B5: SWiM Pay Pty Ltd | C5: =VLOOKUP(B5,Validation!A:B,2,0) -> Shared Center | D5: =VLOOKUP(B5,Validation!A:D,4,0) -> Simrn | E5: =VLOOKUP(B5,Validation!A:E,5,0) -> Vinoth M | F5: Active | G5: =YEAR(L5) -> 2025 | H5: Bank Transfer | I5: USD | J5: =VLOOKUP(I5,'XE rates'!A:D,4,0)*K5 -> 10000 | K5: 10000 | L5: 45717 | M5: =TEXT(L5,"mmm") -> Mar | N5: =$Y$1-R5 -> 476 | O5: =IF(N5<=30, "0-30 days", IF(N5<=60, "31-60 days", IF(N5<=90, "61-90 days", "Over 90+ days"))) -> Over 90+ days | P5: Monthly Billing | Q5: 45749 | R5: 45756 | S5: Outstanding | T5: INV-020425174717 | U5: Yes | V5: Yes | W5: A Letter of Demand (LOD) has been issued, and the account has been suspended. BD has asked client to make partial payment of $25k, awaiting further update. | Y5: =VLOOKUP(T5,'[1]Query result'!$J:$K,2,0) -> 45756 | Z5: =VLOOKUP(T5,'[1]Query result'!$J:$W,14,0) -> 0 | AA5: =K5-Z5 -> 10000
A6: N1 | B6: SWiM Pay Pty Ltd | C6: =VLOOKUP(B6,Validation!A:B,2,0) -> Shared Center | D6: =VLOOKUP(B6,Validation!A:D,4,0) -> Simrn | E6: =VLOOKUP(B6,Validation!A:E,5,0) -> Vinoth M | F6: Active | G6: =YEAR(L6) -> 2025 | H6: Bank Transfer | I6: USD | J6: =VLOOKUP(I6,'XE rates'!A:D,4,0)*K6 -> 10000 | K6: 10000 | L6: 45748 | M6: =TEXT(L6,"mmm") -> Apr | N6: =$Y$1-R6 -> 443 | O6: =IF(N6<=30, "0-30 days", IF(N6<=60, "31-60 days", IF(N6<=90, "61-90 days", "Over 90+ days"))) -> Over 90+ days | P6: Monthly Billing | Q6: 45782 | R6: 45789 | S6: Outstanding | T6: INV-050525114818 | U6: Yes | V6: Yes | W6: A Letter of Demand (LOD) has been issued, and the account has been suspended. BD has asked client to make partial payment of $25k, awaiting further update. | Y6: =VLOOKUP(T6,'[1]Query result'!$J:$K,2,0) -> 45789 | Z6: =VLOOKUP(T6,'[1]Query result'!$J:$W,14,0) -> 0 | AA6: =K6-Z6 -> 10000
A7: N1 | B7: SWiM Pay Pty Ltd | C7: =VLOOKUP(B7,Validation!A:B,2,0) -> Shared Center | D7: =VLOOKUP(B7,Validation!A:D,4,0) -> Simrn | E7: =VLOOKUP(B7,Validation!A:E,5,0) -> Vinoth M | F7: Active | G7: =YEAR(L7) -> 2025 | H7: Bank Transfer | I7: USD | J7: =VLOOKUP(I7,'XE rates'!A:D,4,0)*K7 -> 10000 | K7: 10000 | L7: 45778 | M7: =TEXT(L7,"mmm") -> May | N7: =$Y$1-R7 -> 413 | O7: =IF(N7<=30, "0-30 days", IF(N7<=60, "31-60 days", IF(N7<=90, "61-90 days", "Over 90+ days"))) -> Over 90+ days | P7: Monthly Billing | Q7: 45812 | R7: 45819 | S7: Outstanding | T7: INV-040625165635 | U7: Yes | V7: Yes | W7: A Letter of Demand (LOD) has been issued, and the account has been suspended. BD has asked client to make partial payment of $25k, awaiting further update. | Y7: =VLOOKUP(T7,'[1]Query result'!$J:$K,2,0) -> 45819 | Z7: =VLOOKUP(T7,'[1]Query result'!$J:$W,14,0) -> 0 | AA7: =K7-Z7 -> 10000
A8: N1 | B8: Loadpass LTDA | C8: =VLOOKUP(B8,Validation!A:B,2,0) -> Americas | D8: =VLOOKUP(B8,Validation!A:D,4,0) -> Lia Susin | E8: =VLOOKUP(B8,Validation!A:E,5,0) -> Christina Hutchinson | F8: Active | G8: =YEAR(L8) -> 2025 | H8: Bank Transfer | I8: USD | J8: =VLOOKUP(I8,'XE rates'!A:D,4,0)*K8 -> 3495.5 | K8: 3495.5 | L8: 45839 | M8: =TEXT(L8,"mmm") -> Jul | N8: =$Y$1-R8 -> 351 | O8: =IF(N8<=30, "0-30 days", IF(N8<=60, "31-60 days", IF(N8<=90, "61-90 days", "Over 90+ days"))) -> Over 90+ days | P8: Monthly Billing | Q8: 45874 | R8: 45881 | S8: Outstanding | T8: INV-050825115818 | U8: Yes | V8: No | W8: AM is currently revisiting commercials in place hence this will may take some more time to settle the invoices. | Y8: =VLOOKUP(T8,'[1]Query result'!$J:$K,2,0) -> 45881 | Z8: =VLOOKUP(T8,'[1]Query result'!$J:$W,14,0) -> 0 | AA8: =K8-Z8 -> 3495.5
A9: N1 | B9: Loadpass LTDA | C9: =VLOOKUP(B9,Validation!A:B,2,0) -> Americas | D9: =VLOOKUP(B9,Validation!A:D,4,0) -> Lia Susin | E9: =VLOOKUP(B9,Validation!A:E,5,0) -> Christina Hutchinson | F9: Active | G9: =YEAR(L9) -> 2025 | H9: Bank Transfer | I9: USD | J9: =VLOOKUP(I9,'XE rates'!A:D,4,0)*K9 -> 3485 | K9: 3485 | L9: 45870 | M9: =TEXT(L9,"mmm") -> Aug | N9: =$Y$1-R9 -> 323 | O9: =IF(N9<=30, "0-30 days", IF(N9<=60, "31-60 days", IF(N9<=90, "61-90 days", "Over 90+ days"))) -> Over 90+ days | P9: Monthly Billing | Q9: 45902 | R9: 45909 | S9: Outstanding | T9: INV-020925171323 | U9: Yes | V9: No | W9: AM is currently revisiting commercials in place hence this will may take some more time to settle the invoices. | Y9: =VLOOKUP(T9,'[1]Query result'!$J:$K,2,0) -> 45909 | Z9: =VLOOKUP(T9,'[1]Query result'!$J:$W,14,0) -> 0 | AA9: =K9-Z9 -> 3485
A10: Masspay | B10: FTB HUB S.A.C | C10: =VLOOKUP(B10,Validation!A:B,2,0) -> Shared Center | D10: =VLOOKUP(B10,Validation!A:D,4,0) -> Bhavani | E10: =VLOOKUP(B10,Validation!A:E,5,0) -> NA | F10: Active | G10: =YEAR(L10) -> 2025 | H10: Wallet Debit | I10: USD | J10: =VLOOKUP(I10,'XE rates'!A:D,4,0)*K10 -> 1020 | K10: 1020 | L10: 45901 | M10: =TEXT(L10,"mmm") -> Sep | N10: =$Y$1-R10 -> 295 | O10: =IF(N10<=30, "0-30 days", IF(N10<=60, "31-60 days", IF(N10<=90, "61-90 days", "Over 90+ days"))) -> Over 90+ days | P10: Monthly Billing | Q10: 45931 | R10: 45937 | S10: Force Settlement | T10: SG-FTBHUB-09/2025 | U10: Yes | V10: No | W10: wallet debited, insufficient funds | Y10: =VLOOKUP(T10,'[1]Query result'!$J:$K,2,0) -> 45937 | Z10: =VLOOKUP(T10,'[1]Query result'!$J:$W,14,0) -> 0 | AA10: =K10-Z10 -> 1020
A11: N1 | B11: Loadpass LTDA | C11: =VLOOKUP(B11,Validation!A:B,2,0) -> Americas | D11: =VLOOKUP(B11,Validation!A:D,4,0) -> Lia Susin | E11: =VLOOKUP(B11,Validation!A:E,5,0) -> Christina Hutchinson | F11: Active | G11: =YEAR(L11) -> 2025 | H11: Bank Transfer | I11: USD | J11: =VLOOKUP(I11,'XE rates'!A:D,4,0)*K11 -> 3487.5 | K11: 3487.5 | L11: 45901 | M11: =TEXT(L11,"mmm") -> Sep | N11: =$Y$1-R11 -> 293 | O11: =IF(N11<=30, "0-30 days", IF(N11<=60, "31-60 days", IF(N11<=90, "61-90 days", "Over 90+ days"))) -> Over 90+ days | P11: Monthly Billing | Q11: 45932 | R11: 45939 | S11: Outstanding | T11: INV-021025184847 | U11: Yes | V11: No | W11: AM is currently revisiting commercials in place hence this will may take some more time to settle the invoices. | Y11: =VLOOKUP(T11,'[1]Query result'!$J:$K,2,0) -> 45939 | Z11: =VLOOKUP(T11,'[1]Query result'!$J:$W,14,0) -> 0 | AA11: =K11-Z11 -> 3487.5
A12: Masspay | B12: FTB HUB S.A.C | C12: =VLOOKUP(B12,Validation!A:B,2,0) -> Shared Center | D12: =VLOOKUP(B12,Validation!A:D,4,0) -> Bhavani | E12: =VLOOKUP(B12,Validation!A:E,5,0) -> NA | F12: Active | G12: =YEAR(L12) -> 2025 | H12: Wallet Debit | I12: USD | J12: =VLOOKUP(I12,'XE rates'!A:D,4,0)*K12 -> 1000 | K12: 1000 | L12: 45931 | M12: =TEXT(L12,"mmm") -> Oct | N12: =$Y$1-R12 -> 264 | O12: =IF(N12<=30, "0-30 days", IF(N12<=60, "31-60 days", IF(N12<=90, "61-90 days", "Over 90+ days"))) -> Over 90+ days | P12: Monthly Billing | Q12: 45962 | R12: 45968 | S12: Force Settlement | T12: SG-FTBHUB-10/2025 | U12: Yes | V12: No | W12: wallet debited, insufficient funds | Y12: =VLOOKUP(T12,'[1]Query result'!$J:$K,2,0) -> 45968 | Z12: =VLOOKUP(T12,'[1]Query result'!$J:$W,14,0) -> 0 | AA12: =K12-Z12 -> 1000
A13: N1 | B13: Budgetly Pty Ltd | C13: =VLOOKUP(B13,Validation!A:B,2,0) -> APAC | D13: =VLOOKUP(B13,Validation!A:D,4,0) -> Hao Nguyen | E13: =VLOOKUP(B13,Validation!A:E,5,0) -> Vinoth M | F13: Active | G13: =YEAR(L13) -> 2025 | H13: Bank Transfer | I13: AUD | J13: =VLOOKUP(I13,'XE rates'!A:D,4,0)*K13 -> 962.06719 | K13: 1372.9 | L13: 45901 | M13: =TEXT(L13,"mmm") -> Sep | N13: =$Y$1-R13 -> 243 | O13: =IF(N13<=30, "0-30 days", IF(N13<=60, "31-60 days", IF(N13<=90, "61-90 days", "Over 90+ days"))) -> Over 90+ days | P13: Card Printing and Delivery | Q13: 45958 | R13: 45989 | S13: Partially Paid | T13: INV-281025170000 | U13: Yes | V13: No | W13: Client has raised concerns regarding card deactivation & not willing to pay MMC. AM will send summary to the client including all invoices & share goodwill amount. | Y13: =VLOOKUP(T13,'[1]Query result'!$J:$K,2,0) -> 45989 | Z13: =VLOOKUP(T13,'[1]Query result'!$J:$W,14,0) -> 0 | AA13: =K13-Z13 -> 1372.9
... A21: N1 | B21: Loadpass LTDA | C21: =VLOOKUP(B21,Validation!A:B,2,0) -> Americas | D21: =VLOOKUP(B21,Validation!A:D,4,0) -> Lia Susin | E21: =VLOOKUP(B21,Validation!A:E,5,0) -> Christina Hutchinson | F21: Active | G21: =YEAR(L21) -> 2025 | H21: Bank Transfer | I21: USD | J21: =VLOOKUP(I21,'XE rates'!A:D,4,0)*K21 -> 1786.14 | K21: 1786.14 | L21: 45962 | M21: =TEXT(L21,"mmm") -> Nov | N21: =$Y$1-R21 -> 232 | O21: =IF(N21<=30, "0-30 days", IF(N21<=60, "31-60 days", IF(N21<=90, "61-90 days", "Over 90+ days"))) -> Over 90+ days | P21: Monthly Billing | Q21: 45993 | R21: 46000 | S21: Outstanding | T21: INV-021225201549 | U21: Yes | V21: No | W21: AM is currently revisiting commercials in place hence this will may take some more time to settle the invoices. | Y21: =VLOOKUP(T21,'[1]Query result'!$J:$K,2,0) -> 46000 | Z21: =VLOOKUP(T21,'[1]Query result'!$J:$W,14,0) -> 0 | AA21: =K21-Z21 -> 1786.14
A22: Masspay | B22: GLOBAL ROOTS INC | C22: =VLOOKUP(B22,Validation!A:B,2,0) -> Shared Center | D22: =VLOOKUP(B22,Validation!A:D,4,0) -> Bhavani | E22: =VLOOKUP(B22,Validation!A:E,5,0) -> NA | F22: Active | G22: =YEAR(L22) -> 2025 | H22: Bank Transfer | I22: USD | J22: =VLOOKUP(I22,'XE rates'!A:D,4,0)*K22 -> 2217.6 | K22: 2217.6 | L22: 45992 | M22: =TEXT(L22,"mmm") -> Dec | N22: =$Y$1-R22 -> 193 | O22: =IF(N22<=30, "0-30 days", IF(N22<=60, "31-60 days", IF(N22<=90, "61-90 days", "Over 90+ days"))) -> Over 90+ days | P22: Monthly Billing | Q22: 46024 | R22: 46039 | S22: Overdue | T22: US-GLOBAL ROOTS INC-12/2025 | U22: Yes | V22: No | W22: AM to connect with the client regarding settlement of the 2 invoices, where actuals were billed. | Y22: =VLOOKUP(T22,'[1]Query result'!$J:$K,2,0) -> 46039
A23: N1 | B23: Budgetly Pty Ltd | C23: =VLOOKUP(B23,Validation!A:B,2,0) -> APAC | D23: =VLOOKUP(B23,Validation!A:D,4,0) -> Hao Nguyen | E23: =VLOOKUP(B23,Validation!A:E,5,0) -> Vinoth M | F23: Active | G23: =YEAR(L23) -> 2025 | H23: Bank Transfer | I23: AUD | J23: =VLOOKUP(I23,'XE rates'!A:D,4,0)*K23 -> 832.15974 | K23: 1187.518 | L23: 45992 | M23: =TEXT(L23,"mmm") -> Dec | N23: =$Y$1-R23 -> 174 | O23: =IF(N23<=30, "0-30 days", IF(N23<=60, "31-60 days", IF(N23<=90, "61-90 days", "Over 90+ days"))) -> Over 90+ days | P23: Monthly Billing | Q23: 46028 | R23: 46058 | S23: Outstanding | T23: INV-060126122618 | U23: Yes | V23: No | W23: Client has raised concerns regarding card deactivation & not willing to pay MMC. AM will send summary to the client including all invoices & share goodwill amount. | Y23: =VLOOKUP(T23,'[1]Query result'!$J:$K,2,0) -> 46058 | Z23: =VLOOKUP(T23,'[1]Query result'!$J:$W,14,0) -> 0 | AA23: =K23-Z23 -> 1187.518
A24: N1 | B24: FIRSTKYC PTE. LTD. | C24: =VLOOKUP(B24,Validation!A:B,2,0) -> APAC | D24: =VLOOKUP(B24,Validation!A:D,4,0) -> NA | E24: =VLOOKUP(B24,Validation!A:E,5,0) -> Denis Tan | F24: Active | G24: =YEAR(L24) -> 2025 | H24: Bank Transfer | I24: USD | J24: =VLOOKUP(I24,'XE rates'!A:D,4,0)*K24 -> 1.72 | K24: 1.72 | L24: 45992 | M24: =TEXT(L24,"mmm") -> Dec | N24: =$Y$1-R24 -> 198 | O24: =IF(N24<=30, "0-30 days", IF(N24<=60, "31-60 days", IF(N24<=90, "61-90 days", "Over 90+ days"))) -> Over 90+ days | P24: Monthly Billing | Q24: 46027 | R24: 46034 | S24: Outstanding | T24: INV-050126095427 | U24: Yes | V24: No | W24: Client will settle once lumpsum threshold achieved | Y24: =VLOOKUP(T24,'[1]Query result'!$J:$K,2,0) -> 46034 | Z24: =VLOOKUP(T24,'[1]Query result'!$J:$W,14,0) -> 0 | AA24: =K24-Z24 -> 1.72
A25: N1 | B25: Istanbul Ödeme ve Elektronik Para A.S | C25: =VLOOKUP(B25,Validation!A:B,2,0) -> MEA | D25: =VLOOKUP(B25,Validation!A:D,4,0) -> Jerome Coelho | E25: =VLOOKUP(B25,Validation!A:E,5,0) -> Ashraf Omran | F25: Active | G25: =YEAR(L25) -> 2025 | H25: Bank Transfer | I25: USD | J25: =VLOOKUP(I25,'XE rates'!A:D,4,0)*K25 -> 2500 | K25: 2500 | L25: 45992 | M25: =TEXT(L25,"mmm") -> Dec | N25: =$Y$1-R25 -> 198 | O25: =IF(N25<=30, "0-30 days", IF(N25<=60, "31-60 days", IF(N25<=90, "61-90 days", "Over 90+ days"))) -> Over 90+ days | P25: Monthly Billing | Q25: 46027 | R25: 46034 | S25: Force Settlement | T25: INV-050126150313 | U25: Yes | V25: No | W25: AM has asked to keep the invoices pending until funds are received. | Y25: =VLOOKUP(T25,'[1]Query result'!$J:$K,2,0) -> 46034 | Z25: =VLOOKUP(T25,'[1]Query result'!$J:$W,14,0) -> 0 | AA25: =K25-Z25 -> 2500
A26: N1 | B26: JPMORGAN CHASE BANK | C26: =VLOOKUP(B26,Validation!A:B,2,0) -> EU/UK | D26: =VLOOKUP(B26,Validation!A:D,4,0) -> Sachli Zare | E26: =VLOOKUP(B26,Validation!A:E,5,0) -> NA | F26: Active | G26: =YEAR(L26) -> 2025 | H26: Bank Transfer | I26: USD | J26: =VLOOKUP(I26,'XE rates'!A:D,4,0)*K26 -> 2.5 | K26: 2.5 | L26: 45992 | M26: =TEXT(L26,"mmm") -> Dec | N26: =$Y$1-R26 -> 198 | O26: =IF(N26<=30, "0-30 days", IF(N26<=60, "31-60 days", IF(N26<=90, "61-90 days", "Over 90+ days"))) -> Over 90+ days | P26: Monthly Billing | Q26: 46027 | R26: 46034 | S26: Outstanding | T26: INV-050126184308 | U26: Yes | V26: No | W26: Partially settled by the client | Y26: =VLOOKUP(T26,'[1]Query result'!$J:$K,2,0) -> 46034 | Z26: =VLOOKUP(T26,'[1]Query result'!$J:$W,14,0) -> 0 | AA26: =K26-Z26 -> 2.5
A27: N1 | B27: Loadpass LTDA | C27: =VLOOKUP(B27,Validation!A:B,2,0) -> Americas | D27: =VLOOKUP(B27,Validation!A:D,4,0) -> Lia Susin | E27: =VLOOKUP(B27,Validation!A:E,5,0) -> Christina Hutchinson | F27: Active | G27: =YEAR(L27) -> 2025 | H27: Bank Transfer | I27: USD | J27: =VLOOKUP(I27,'XE rates'!A:D,4,0)*K27 -> 1659.62 | K27: 1659.62 | L27: 45992 | M27: =TEXT(L27,"mmm") -> Dec | N27: =$Y$1-R27 -> 198 | O27: =IF(N27<=30, "0-30 days", IF(N27<=60, "31-60 days", IF(N27<=90, "61-90 days", "Over 90+ days"))) -> Over 90+ days | P27: Monthly Billing | Q27: 46027 | R27: 46034 | S27: Outstanding | T27: INV-050126153219 | U27: Yes | V27: No | W27: AM is currently revisiting commercials in place hence this will may take some more time to settle the invoices. | Y27: =VLOOKUP(T27,'[1]Query result'!$J:$K,2,0) -> 46034 | Z27: =VLOOKUP(T27,'[1]Query result'!$J:$W,14,0) -> 0 | AA27: =K27-Z27 -> 1659.62
A28: N1 | B28: Budgetly Pty Ltd | C28: =VLOOKUP(B28,Validation!A:B,2,0) -> APAC | D28: =VLOOKUP(B28,Validation!A:D,4,0) -> Hao Nguyen | E28: =VLOOKUP(B28,Validation!A:E,5,0) -> Vinoth M | F28: Active | G28: =YEAR(L28) -> 2025 | H28: Bank Transfer | I28: AUD | J28: =VLOOKUP(I28,'XE rates'!A:D,4,0)*K28 -> 1558.6694 | K28: 2224.27 | L28: 45992 | M28: =TEXT(L28,"mmm") -> Dec | N28: =$Y$1-R28 -> 156 | O28: =IF(N28<=30, "0-30 days", IF(N28<=60, "31-60 days", IF(N28<=90, "61-90 days", "Over 90+ days"))) -> Over 90+ days | P28: Card Printing and Delivery | Q28: 46045 | R28: 46076 | S28: Outstanding | T28: INV-230126170000 | U28: Yes | V28: No | W28: Client has raised concerns regarding card deactivation & not willing to pay MMC. AM will send summary to the client including all invoices & share goodwill amount.
A29: N1 | B29: Budgetly Pty Ltd | C29: =VLOOKUP(B29,Validation!A:B,2,0) -> APAC | D29: =VLOOKUP(B29,Validation!A:D,4,0) -> Hao Nguyen | E29: =VLOOKUP(B29,Validation!A:E,5,0) -> Vinoth M | F29: Active | G29: =YEAR(L29) -> 2026 | H29: Bank Transfer | I29: AUD | J29: =VLOOKUP(I29,'XE rates'!A:D,4,0)*K29 -> 3733.176 | K29: 5327.359 | L29: 46023 | M29: =TEXT(L29,"mmm") -> Jan | N29: =$Y$1-R29 -> 165 | O29: =IF(N29<=30, "0-30 days", IF(N29<=60, "31-60 days", IF(N29<=90, "61-90 days", "Over 90+ days"))) -> Over 90+ days | P29: Monthly Billing | Q29: 46060 | R29: 46067 | S29: Outstanding | T29: INV-070226133026 | U29: Yes | V29: No | W29: Client has raised concerns regarding card deactivation & not willing to pay MMC. AM will send summary to the client including all invoices & share goodwill amount.
A30: N1 | B30: FIRSTKYC PTE. LTD. | C30: =VLOOKUP(B30,Validation!A:B,2,0) -> APAC | D30: =VLOOKUP(B30,Validation!A:D,4,0) -> NA | E30: =VLOOKUP(B30,Validation!A:E,5,0) -> Denis Tan | F30: Active | G30: =YEAR(L30) -> 2026 | H30: Bank Transfer | I30: USD | J30: =VLOOKUP(I30,'XE rates'!A:D,4,0)*K30 -> 14.19 | K30: 14.19 | L30: 46023 | M30: =TEXT(L30,"mmm") -> Jan | N30: =$Y$1-R30 -> 166 | O30: =IF(N30<=30, "0-30 days", IF(N30<=60, "31-60 days", IF(N30<=90, "61-90 days", "Over 90+ days"))) -> Over 90+ days | P30: Monthly Billing | Q30: 46059 | R30: 46066 | S30: Outstanding | T30: INV-060226120820 | U30: Yes | V30: No | W30: Client will settle once lumpsum threshold achieved
A31: N1 | B31: Istanbul Ödeme ve Elektronik Para A.S | C31: =VLOOKUP(B31,Validation!A:B,2,0) -> MEA | D31: =VLOOKUP(B31,Validation!A:D,4,0) -> Jerome Coelho | E31: =VLOOKUP(B31,Validation!A:E,5,0) -> Ashraf Omran | F31: Active | G31: =YEAR(L31) -> 2026 | H31: Bank Transfer | I31: USD | J31: =VLOOKUP(I31,'XE rates'!A:D,4,0)*K31 -> 2500 | K31: 2500 | L31: 46023 | M31: =TEXT(L31,"mmm") -> Jan | N31: =$Y$1-R31 -> 170 | O31: =IF(N31<=30, "0-30 days", IF(N31<=60, "31-60 days", IF(N31<=90, "61-90 days", "Over 90+ days"))) -> Over 90+ days | P31: Monthly Billing | Q31: 46055 | R31: 46062 | S31: Force Settlement | T31: INV-020226182425 | U31: Yes | V31: No | W31: AM has asked to keep the invoices pending until funds are received.
A32: N1 | B32: MULTIPLIER TECHNOLOGIES PTE. LTD | C32: =VLOOKUP(B32,Validation!A:B,2,0) -> Shared Center | D32: =VLOOKUP(B32,Validation!A:D,4,0) -> Sanat Patakar | E32: =VLOOKUP(B32,Validation!A:E,5,0) -> Vinoth M | F32: Active | G32: =YEAR(L32) -> 2026 | H32: Bank Transfer | I32: USD | J32: =VLOOKUP(I32,'XE rates'!A:D,4,0)*K32 -> 2965 | K32: 2965 | L32: 46023 | M32: =TEXT(L32,"mmm") -> Jan | N32: =$Y$1-R32 -> 167 | O32: =IF(N32<=30, "0-30 days", IF(N32<=60, "31-60 days", IF(N32<=90, "61-90 days", "Over 90+ days"))) -> Over 90+ days | P32: Monthly Billing | Q32: 46058 | R32: 46065 | S32: Outstanding | T32: INV-050226133127 | U32: Yes | V32: Yes | W32: Payment has been received for two invoices; pending update on settlement of the remaining balance.
A33: N1 | B33: MyBeacon Services Inc.-Verify | C33: =VLOOKUP(B33,Validation!A:B,2,0) -> Americas | D33: =VLOOKUP(B33,Validation!A:D,4,0) -> Tanu Arora | E33: =VLOOKUP(B33,Validation!A:E,5,0) -> Michael Bermingham | F33: Active | G33: =YEAR(L33) -> 2026 | H33: Bank Transfer | I33: USD | J33: =VLOOKUP(I33,'XE rates'!A:D,4,0)*K33 -> 36.32 | K33: 36.32 | L33: 46023 | M33: =TEXT(L33,"mmm") -> Jan | N33: =$Y$1-R33 -> 168 | O33: =IF(N33<=30, "0-30 days", IF(N33<=60, "31-60 days", IF(N33<=90, "61-90 days", "Over 90+ days"))) -> Over 90+ days | P33: Monthly Billing | Q33: 46057 | R33: 46064 | S33: Outstanding | T33: INV-040226185603 | U33: Yes | V33: No | W33: Client does not want to bear the return charges, discussions are currently ongoing with the client and Mike to reach a resolution.
A34: N1 | B34: Budgetly Pty Ltd | C34: =VLOOKUP(B34,Validation!A:B,2,0) -> APAC | D34: =VLOOKUP(B34,Validation!A:D,4,0) -> Hao Nguyen | E34: =VLOOKUP(B34,Validation!A:E,5,0) -> Vinoth M | F34: Active | G34: =YEAR(L34) -> 2026 | H34: Bank Transfer | I34: AUD | J34: =VLOOKUP(I34,'XE rates'!A:D,4,0)*K34 -> 38.905944 | K34: 55.52 | L34: 46023 | M34: =TEXT(L34,"mmm") -> Jan | N34: =$Y$1-R34 -> 131 | O34: =IF(N34<=30, "0-30 days", IF(N34<=60, "31-60 days", IF(N34<=90, "61-90 days", "Over 90+ days"))) -> Over 90+ days | P34: Card Printing and Delivery | Q34: 46073 | R34: 46101 | S34: Outstanding | T34: INV-200226170000 | U34: Yes | V34: No | W34: Client has raised concerns regarding card deactivation & not willing to pay MMC. AM will send summary to the client including all invoices & share goodwill amount.
A35: N1 | B35: Budgetly Pty Ltd | C35: =VLOOKUP(B35,Validation!A:B,2,0) -> APAC | D35: =VLOOKUP(B35,Validation!A:D,4,0) -> Hao Nguyen | E35: =VLOOKUP(B35,Validation!A:E,5,0) -> Vinoth M | F35: Active | G35: =YEAR(L35) -> 2026 | H35: Bank Transfer | I35: AUD | J35: =VLOOKUP(I35,'XE rates'!A:D,4,0)*K35 -> 2696.4181 | K35: 3847.873 | L35: 46054 | M35: =TEXT(L35,"mmm") -> Feb | N35: =$Y$1-R35 -> 117 | O35: =IF(N35<=30, "0-30 days", IF(N35<=60, "31-60 days", IF(N35<=90, "61-90 days", "Over 90+ days"))) -> Over 90+ days | P35: Monthly Billing | Q35: 46085 | R35: 46115 | S35: Outstanding | T35: INV-040326125850 | U35: Yes | V35: No | W35: Client has raised concerns regarding card deactivation & not willing to pay MMC. AM will send summary to the client including all invoices & share goodwill amount.
A36: N1 | B36: FIRSTKYC PTE. LTD. | C36: =VLOOKUP(B36,Validation!A:B,2,0) -> APAC | D36: =VLOOKUP(B36,Validation!A:D,4,0) -> NA | E36: =VLOOKUP(B36,Validation!A:E,5,0) -> Denis Tan | F36: Active | G36: =YEAR(L36) -> 2026 | H36: Bank Transfer | I36: USD | J36: =VLOOKUP(I36,'XE rates'!A:D,4,0)*K36 -> 6.88 | K36: 6.88 | L36: 46054 | M36: =TEXT(L36,"mmm") -> Feb | N36: =$Y$1-R36 -> 140 | O36: =IF(N36<=30, "0-30 days", IF(N36<=60, "31-60 days", IF(N36<=90, "61-90 days", "Over 90+ days"))) -> Over 90+ days | P36: Monthly Billing | Q36: 46085 | R36: 46092 | S36: Outstanding | T36: INV-040326132912 | U36: Yes | V36: No | W36: Client will settle once lumpsum threshold achieved
A37: N1 | B37: Istanbul Ödeme ve Elektronik Para A.S | C37: =VLOOKUP(B37,Validation!A:B,2,0) -> MEA | D37: =VLOOKUP(B37,Validation!A:D,4,0) -> Jerome Coelho | E37: =VLOOKUP(B37,Validation!A:E,5,0) -> Ashraf Omran | F37: Active | G37: =YEAR(L37) -> 2026 | H37: Bank Transfer | I37: USD | J37: =VLOOKUP(I37,'XE rates'!A:D,4,0)*K37 -> 2500 | K37: 2500 | L37: 46054 | M37: =TEXT(L37,"mmm") -> Feb | N37: =$Y$1-R37 -> 142 | O37: =IF(N37<=30, "0-30 days", IF(N37<=60, "31-60 days", IF(N37<=90, "61-90 days", "Over 90+ days"))) -> Over 90+ days | P37: Monthly Billing | Q37: 46083 | R37: 46090 | S37: Force Settlement | T37: INV-020326191014 | U37: Yes | V37: No | W37: AM has asked to keep the invoices pending until funds are received.
A38: N1 | B38: JPMORGAN CHASE BANK | C38: =VLOOKUP(B38,Validation!A:B,2,0) -> EU/UK | D38: =VLOOKUP(B38,Validation!A:D,4,0) -> Sachli Zare | E38: =VLOOKUP(B38,Validation!A:E,5,0) -> NA | F38: Active | G38: =YEAR(L38) -> 2026 | H38: Bank Transfer | I38: USD | J38: =VLOOKUP(I38,'XE rates'!A:D,4,0)*K38 -> 89.8 | K38: 89.8 | L38: 46054 | M38: =TEXT(L38,"mmm") -> Feb | N38: =$Y$1-R38 -> 140 | O38: =IF(N38<=30, "0-30 days", IF(N38<=60, "31-60 days", IF(N38<=90, "61-90 days", "Over 90+ days"))) -> Over 90+ days | P38: Monthly Billing | Q38: 46085 | R38: 46092 | S38: Partially Paid | T38: INV-040326132449 | U38: Yes | V38: No | W38: Partially settled by the client
A39: N1 | B39: Loadpass LTDA | C39: =VLOOKUP(B39,Validation!A:B,2,0) -> Americas | D39: =VLOOKUP(B39,Validation!A:D,4,0) -> Lia Susin | E39: =VLOOKUP(B39,Validation!A:E,5,0) -> Christina Hutchinson | F39: Active | G39: =YEAR(L39) -> 2026 | H39: Bank Transfer | I39: USD | J39: =VLOOKUP(I39,'XE rates'!A:D,4,0)*K39 -> 608.97 | K39: 608.97 | L39: 46054 | M39: =TEXT(L39,"mmm") -> Feb | N39: =$Y$1-R39 -> 141 | O39: =IF(N39<=30, "0-30 days", IF(N39<=60, "31-60 days", IF(N39<=90, "61-90 days", "Over 90+ days"))) -> Over 90+ days | P39: Monthly Billing | Q39: 46084 | R39: 46091 | S39: Outstanding | T39: INV-030326144903 | U39: Yes | V39: No | W39: AM is currently revisiting commercials in place hence this will may take some more time to settle the invoices.
... A55: Masspay | B55: Qatar National Bank (Q.P.S.C.) | C55: =VLOOKUP(B55,Validation!A:B,2,0) -> MEA | D55: =VLOOKUP(B55,Validation!A:D,4,0) -> Jerome Coelho | E55: =VLOOKUP(B55,Validation!A:E,5,0) -> Rohit Bammi | F55: Active | G55: =YEAR(L55) -> 2026 | H55: Bank Transfer | I55: USD | J55: =VLOOKUP(I55,'XE rates'!A:D,4,0)*K55 -> 4029.75 | K55: 4029.75 | L55: 46113 | M55: =TEXT(L55,"mmm") -> Apr | N55: =$Y$1-R55 -> 79 | O55: =IF(N55<=30, "0-30 days", IF(N55<=60, "31-60 days", IF(N55<=90, "61-90 days", "Over 90+ days"))) -> 61-90 days | P55: Monthly Billing | Q55: 46146 | R55: 46153 | S55: Overdue | T55: SG-Qatar National Bank (Q.P.S.C.)-04/2026 | U55: Yes | V55: No | W55: No response from the client post reminder sent
A56: N1 | B56: Emirates Islamic Bank PJSC | C56: =VLOOKUP(B56,Validation!A:B,2,0) -> MEA | D56: =VLOOKUP(B56,Validation!A:D,4,0) -> Jerome Coelho | E56: =VLOOKUP(B56,Validation!A:E,5,0) -> Rohit Bammi | F56: Active | G56: =YEAR(L56) -> 2026 | H56: Bank Transfer | I56: USD | J56: =VLOOKUP(I56,'XE rates'!A:D,4,0)*K56 -> 3736.5 | K56: 3736.5 | L56: 46113 | M56: =TEXT(L56,"mmm") -> Apr | N56: =$Y$1-R56 -> 79 | O56: =IF(N56<=30, "0-30 days", IF(N56<=60, "31-60 days", IF(N56<=90, "61-90 days", "Over 90+ days"))) -> 61-90 days | P56: Monthly Billing | Q56: 46146 | R56: 46153 | S56: Outstanding | T56: INV-040526204049 | U56: Yes | V56: No
A57: N1 | B57: EVERWIN REMITTANCE AND EXCHANGE CO LIMITED | C57: =VLOOKUP(B57,Validation!A:B,2,0) -> APAC | D57: =VLOOKUP(B57,Validation!A:D,4,0) -> NA | E57: =VLOOKUP(B57,Validation!A:E,5,0) -> Lisa Sung | F57: Active | G57: =YEAR(L57) -> 2026 | H57: Bank Transfer | I57: USD | J57: =VLOOKUP(I57,'XE rates'!A:D,4,0)*K57 -> 46001.45 | K57: 46001.45 | L57: 46143 | M57: =TEXT(L57,"mmm") -> May | N57: =$Y$1-R57 -> 72 | O57: =IF(N57<=30, "0-30 days", IF(N57<=60, "31-60 days", IF(N57<=90, "61-90 days", "Over 90+ days"))) -> 61-90 days | P57: Monthly Billing | Q57: 46153 | R57: 46160 | S57: Partially Paid | T57: INV-110526145754 | U57: Yes | V57: No
A58: N1 | B58: Express Hub Services Pty Ltd | C58: =VLOOKUP(B58,Validation!A:B,2,0) -> APAC | D58: =VLOOKUP(B58,Validation!A:D,4,0) -> NA | E58: =VLOOKUP(B58,Validation!A:E,5,0) -> Wendy zhai | F58: Active | G58: =YEAR(L58) -> 2026 | H58: Bank Transfer | I58: AUD | J58: =VLOOKUP(I58,'XE rates'!A:D,4,0)*K58 -> 2804.7738 | K58: 4002.5 | L58: 46113 | M58: =TEXT(L58,"mmm") -> Apr | N58: =$Y$1-R58 -> 78 | O58: =IF(N58<=30, "0-30 days", IF(N58<=60, "31-60 days", IF(N58<=90, "61-90 days", "Over 90+ days"))) -> 61-90 days | P58: Monthly Billing | Q58: 46147 | R58: 46154 | S58: Partially Paid | T58: INV-050526150527 | U58: Yes | V58: No | W58: Debited their wallet balance
A59: N1 | B59: FIRSTKYC PTE. LTD. | C59: =VLOOKUP(B59,Validation!A:B,2,0) -> APAC | D59: =VLOOKUP(B59,Validation!A:D,4,0) -> NA | E59: =VLOOKUP(B59,Validation!A:E,5,0) -> Denis Tan | F59: Active | G59: =YEAR(L59) -> 2026 | H59: Bank Transfer | I59: USD | J59: =VLOOKUP(I59,'XE rates'!A:D,4,0)*K59 -> 37.84 | K59: 37.84 | L59: 46113 | M59: =TEXT(L59,"mmm") -> Apr | N59: =$Y$1-R59 -> 79 | O59: =IF(N59<=30, "0-30 days", IF(N59<=60, "31-60 days", IF(N59<=90, "61-90 days", "Over 90+ days"))) -> 61-90 days | P59: Monthly Billing | Q59: 46146 | R59: 46153 | S59: Outstanding | T59: INV-040526162158 | U59: Yes | V59: No | W59: Client will settle once lumpsum threshold achieved
A60: N1 | B60: JPMORGAN CHASE BANK | C60: =VLOOKUP(B60,Validation!A:B,2,0) -> EU/UK | D60: =VLOOKUP(B60,Validation!A:D,4,0) -> Sachli Zare | E60: =VLOOKUP(B60,Validation!A:E,5,0) -> NA | F60: Active | G60: =YEAR(L60) -> 2026 | H60: Bank Transfer | I60: USD | J60: =VLOOKUP(I60,'XE rates'!A:D,4,0)*K60 -> 99.6 | K60: 99.6 | L60: 46113 | M60: =TEXT(L60,"mmm") -> Apr | N60: =$Y$1-R60 -> 79 | O60: =IF(N60<=30, "0-30 days", IF(N60<=60, "31-60 days", IF(N60<=90, "61-90 days", "Over 90+ days"))) -> 61-90 days | P60: Monthly Billing | Q60: 46146 | R60: 46153 | S60: Outstanding | T60: INV-040526200003 | U60: Yes | V60: No | W60: Partially settled by the client
A61: N1 | B61: MULTIPLIER TECHNOLOGIES PTE. LTD | C61: =VLOOKUP(B61,Validation!A:B,2,0) -> Shared Center | D61: =VLOOKUP(B61,Validation!A:D,4,0) -> Sanat Patakar | E61: =VLOOKUP(B61,Validation!A:E,5,0) -> Vinoth M | F61: Active | G61: =YEAR(L61) -> 2026 | H61: Bank Transfer | I61: USD | J61: =VLOOKUP(I61,'XE rates'!A:D,4,0)*K61 -> 2954.5 | K61: 2954.5 | L61: 46113 | M61: =TEXT(L61,"mmm") -> Apr | N61: =$Y$1-R61 -> 79 | O61: =IF(N61<=30, "0-30 days", IF(N61<=60, "31-60 days", IF(N61<=90, "61-90 days", "Over 90+ days"))) -> 61-90 days | P61: Monthly Billing | Q61: 46146 | R61: 46153 | S61: Outstanding | T61: INV-040526195142 | U61: Yes | V61: Yes | W61: Payment has been received for two invoices; pending update on settlement of the remaining balance.
A62: N1 | B62: MyBeacon Services Inc. | C62: =VLOOKUP(B62,Validation!A:B,2,0) -> Americas | D62: =VLOOKUP(B62,Validation!A:D,4,0) -> Tanu Arora | E62: =VLOOKUP(B62,Validation!A:E,5,0) -> Michael Bermingham | F62: Active | G62: =YEAR(L62) -> 2026 | H62: Bank Transfer | I62: CAD | J62: =VLOOKUP(I62,'XE rates'!A:D,4,0)*K62 -> 38.337743 | K62: 54.05 | L62: 46113 | M62: =TEXT(L62,"mmm") -> Apr | N62: =$Y$1-R62 -> 78 | O62: =IF(N62<=30, "0-30 days", IF(N62<=60, "31-60 days", IF(N62<=90, "61-90 days", "Over 90+ days"))) -> 61-90 days | P62: Monthly Billing | Q62: 46147 | R62: 46154 | S62: Outstanding | T62: INV-050526163450 | U62: Yes | V62: No | W62: Client does not want to bear the return charges, discussions are currently ongoing with the client and Mike to reach a resolution.
...

Sheet Rebates
A1: Platform | B1: Customer Label | C1: Region | D1: Account Manager | E1: BD | F1: Client Status | G1: Year | H1: Settlement Type | I1: Currency | J1: USD AMOUNT | K1: Invoice Amount | L1: Billing Period | M1: Month | N1: Days | O1: Ageing Tier | P1: Fee Type | Q1: Invoice Date | R1: Due Date | S1: Invoice Status | T1: Invoice Number | U1: Reminder Sent | V1: LOD | W1: AR's Comments | X1: AM's Comments
A2: N1 | B2: Al Muzaini Exchange | C2: ME | D2: Jerome Coelho | E2: Ashraf Omran | F2: Active | G2: 2025 | H2: Account Settlement | I2: USD | J2: -48 | K2: -48 | L2: 45870 | M2: Aug | N2: 293 | O2: Over 90+ days | P2: Credit Note-Waive off | Q2: 45903 | R2: 45910 | S2: Partially Paid | T2: CN-INV-030925182457 | Y2: Partially Paid
A3: N1 | B3: Aspire FT Pte Ltd | C3: APAC | D3: Shi Yin | E3: Gitesh Athavale | F3: Active | G3: 2026 | H3: Account Settlement | I3: SGD | J3: -25787.318 | K3: -32883.286 | L3: 46143 | M3: May | N3: -4 | O3: 0-30 days | P3: Monthly Billing | Q3: 46177 | R3: 46207 | S3: Invoice Sent | T3: INV-040626125945 | Y3: Invoice Sent
A4: N1 | B4: Loadpass LTDA | C4: USA | D4: Lia Susin | E4: Christina Hutchinson | F4: Active | G4: 2026 | H4: Account Settlement | I4: USD | J4: -152.91 | K4: -152.91 | L4: 46023 | M4: Jan | N4: 140 | O4: Over 90+ days | P4: Monthly Billing | Q4: 46056 | R4: 46063 | S4: Outstanding | T4: INV-030226233006 | Y4: Outstanding
A5: N1 | B5: Mizzen Digital DMCC | C5: ME | D5: Jerome Coelho | E5: Rohit Bammi | F5: Active | G5: 2026 | H5: Account Settlement | I5: USD | J5: -2954.5 | K5: -2954.5 | L5: 46143 | M5: May | N5: 19 | O5: 0-30 days | P5: Credit Note-Waived Off | Q5: 46177 | R5: 46184 | S5: Outstanding | T5: CN-INV-030626132939 | Y5: Outstanding
A6: N1 | B6: Mizzen Digital DMCC | C6: ME | D6: Jerome Coelho | E6: Rohit Bammi | F6: Active | G6: 2026 | H6: Account Settlement | I6: USD | J6: -232.06 | K6: -232.06 | L6: 46143 | M6: May | N6: 19 | O6: 0-30 days | P6: Monthly Billing | Q6: 46177 | R6: 46184 | S6: Outstanding | T6: INV-030626145124 | Y6: Outstanding
A7: N1 | B7: Monex Canada Inc | C7: USA | D7: Tulio Lima | E7: Michael Bermingham | F7: Active | G7: 2026 | H7: Account Settlement | I7: USD | J7: -2132.65 | K7: -2132.65 | L7: 46174 | M7: Jun | N7: 6 | O7: 0-30 days | P7: Credit Note-Write-Off | Q7: 46190 | R7: 46197 | S7: Invoice Sent | T7: CN-INV-170626175259 | Y7: Outstanding
A8: N1 | B8: VOLOPAY.CO PTE. LTD. | C8: APAC | D8: XiaoXiao | E8: Gitesh Athavale | F8: Active | G8: 2026 | H8: Account Settlement | I8: USD | J8: -3325.1822 | K8: -3325.1822 | L8: 46143 | M8: May | N8: 19 | O8: 0-30 days | P8: Monthly Billing | Q8: 46177 | R8: 46184 | S8: Outstanding | T8: INV-040626092813 | Y8: Outstanding
J9: =SUM(J2:J8) -> -34632.62

Sheet XE rates
A1: Currency | B1: Name | C1: Units per USD | D1: USD per unit
A2: USD | B2: US Dollar | C2: 1 | D2: 1
A3: EUR | B3: Euro | C3: 0.8766387 | D3: 1.1407208
A4: GBP | B4: British Pound | C4: 0.74780878 | D4: 1.3372402
A5: INR | B5: Indian Rupee | C5: 96.290192 | D5: 0.010385274
A6: AUD | B6: Australian Dollar | C6: 1.4270313 | D6: 0.70075547
A7: CAD | B7: Canadian Dollar | C7: 1.4098378 | D7: 0.70930144
A8: SGD | B8: Singapore Dollar | C8: 1.2917306 | D8: 0.77415521
A9: CHF | B9: Swiss Franc | C9: 0.81230058 | D9: 1.2310714
A10: MYR | B10: Malaysian Ringgit | C10: 4.0888767 | D10: 0.24456594
A11: JPY | B11: Japanese Yen | C11: 163.02258 | D11: 0.0061341197
A12: CNY | B12: Chinese Yuan Renminbi | C12: 6.7707654 | D12: 0.14769379
A13: NZD | B13: New Zealand Dollar | C13: 1.7149073 | D13: 0.58312189
... A194: ZWG | B194: Zimbabwean Dollar | C194: 25.324496 | D194: 0.039487459

Sheet Validation
A1: Customer Label | B1: Region | C1: Region2 | D1: Account Manager | E1: BD
A2: Stylopay Pte. Ltd | B2: APAC | C2: APAC | D2: XiaoXiao | E2: NA
A3: PayQuicker LLC | B3: Americas | C3: Americas | D3: Terminated | E3: Kyle Reny
A4: Varni Tech Inc | B4: APAC | C4: APAC | D4: Terminated | E4: Gitesh Athavale
A5: aerapass pte. ltd | B5: APAC | C5: APAC | D5: Terminated | E5: Gitesh Athavale
A6: Knox Payments Ltd. | B6: Americas | C6: Americas | D6: Tanu Arora | E6: NA
A7: TClub Inc. | B7: Americas | C7: Americas | D7: Terminated | E7: NA
A8: Transwap Private Limited | B8: Shared Center | C8: Shared Center | D8: Mrinal | E8: Gitesh Athavale
A9: Widoph Remit | B9: Shared Center | C9: Shared Center | D9: NA | E9: Vinoth M
A10: MeshPay UK | B10: EU/UK | C10: UK | D10: Will Turner | E10: Gitesh Athavale
A11: MeshPay UK Ltd | B11: EU/UK | C11: UK | D11: Will Turner | E11: Gitesh Athavale
A12: SPROUT CORPORATE SERVICES PTE LTD | B12: APAC | C12: APAC | D12: Terminated | E12: Gitesh Athavale
... A14: Coda Payments | B14: Shared Center | C14: Shared Center | D14: Sanat Patakar | E14: NA
A15: Al Dhahery Money Exchange | B15: MEA | C15: =B15 -> MEA | D15: Jerome Coelho | E15: Rohit Bammi
A16: coda payments malaysia - aplikasi | B16: SME | C16: SME | D16: Leon Lim | E16: NA
A17: Cash In Asia Pte Ltd | B17: APAC | C17: APAC | D17: Terminated | E17: Gitesh Athavale
A18: Hedgewiz Pure Risk Management Solutions Ltd | B18: EU/UK | C18: EU | D18: Terminated | E18: NA
A19: Hedgewiz Pure Risk Management Solutions Ltd - EU | B19: EU/UK | C19: EU | D19: Terminated | E19: NA
A20: Hedgewiz Pure Risk Management Solutions Ltd -UK | B20: EU/UK | C20: EU | D20: Terminated | E20: NA
A21: Hedgewiz Pure Risk Management Solutions Ltd -US | B21: EU/UK | C21: EU | D21: Terminated | E21: NA
A22: MeshPay EU B.V. | B22: EU/UK | C22: EU | D22: Will Turner | E22: Gitesh Athavale
A23: Pay Set Limited | B23: EU/UK | C23: EU | D23: Terminated | E23: NA
A24: Photon Dance (HongKong) Limited | B24: APAC | C24: APAC | D24: Terminated | E24: Gitesh Athavale
A25: UTU Rewards S.R.L. | B25: APAC | C25: APAC | D25: Terminated | E25: Gitesh Athavale
A26: Yondr Money Pty Ltd | B26: APAC | C26: APAC | D26: Hao Nguyen | E26: NA
A27: Skrill Ltd | B27: EU/UK | C27: EU | D27: Will Turner | E27: NA
A28: Paysafe Financial Services Limited | B28: EU/UK | C28: EU | D28: Will Turner | E28: NA
A29: SAAD EXCHANGE | B29: MEA | C29: =B29 -> MEA | D29: Jerome Coelho | E29: Rohit Bammi
A30: Qolo Inc. | B30: Shared Center | C30: Shared Centre | D30: Sakshi Shanbhag | E30: Kyle Reny
A31: Azimo Limited. | B31: EU/UK | C31: UK | D31: Sachli Zare | E31: Gitesh Athavale
A32: Bud Infrastructure Limited | B32: Shared Center | C32: Shared Centre | D32: Terminated | E32: Michael Bermingham
A33: GET GLOBAL HOLDINGS PTE LTD | B33: APAC | C33: APAC | D33: Terminated | E33: Gitesh Athavale
A34: OWLPAY HOLDINGS PTE. LTD. | B34: Shared Center | C34: Shared Center | D34: Bhavani | E34: Gitesh Athavale
A35: Pelican General Limited | B35: APAC | C35: APAC | D35: Terminated | E35: Lisa Sung
A36: VOLOPAY.CO PTE. LTD. | B36: APAC | C36: APAC | D36: XiaoXiao | E36: Gitesh Athavale
A37: A.D. Financial (AUS) Pty Ltd | B37: Shared Center | C37: Shared center | D37: Sanat Patakar | E37: Vinoth M
A38: AFT HK Limited | B38: APAC | C38: APAC | D38: Shi Yin | E38: Gitesh Athavale
A39: Aspire FT Pte Ltd | B39: APAC | C39: APAC | D39: Shi Yin | E39: Gitesh Athavale
A40: Budgetly Pty Ltd | B40: APAC | C40: APAC | D40: Hao Nguyen | E40: Vinoth M
A41: CAMBIONET CORRETORA DE CAMBIO LTDA | B41: Americas | C41: Americas | D41: Terminated | E41: Lia Susin
...

Sheet RevOPs mapping
A1: Clients | B1: region | C1: Product | D1: AM | I1: Sr. No | J1: Client Name | K1: AM Name
A2: RIPPLING PAYMENTS INC | B2: AMERICAS | C2: Payouts | D2: Tanu Arora | I2: 1 | J2: ATLANTIC PARTNERS ASIA | K2: Sanat
A3: CURRENCY CLOUD | B3: APAC | C3: Payouts | D3: XiaoXiao | I3: 2 | J3: WAN GUO GROUP | K3: Sanat
A4: GLOBAL81 | B4: AMERICAS | C4: Payouts | D4: tulio lima | I4: 3 | J4: ORBIT MONEY | K4: Sakshi
A5: GUSTO US | B5: AMERICAS | C5: Payouts | D5: Tanu Arora | I5: 4 | J5: AD FINANCIAL | K5: Sanat
A6: WORLDPAY AP LTD | B6: EUROPE-Non Travel | C6: Payouts | D6: Sachli Zare | I6: 5 | J6: NIURAL | K6: Mrinal
A7: MASTERCARD TRANSACTION SERVICES (EUROPE) SA | B7: EUROPE-Non Travel | C7: Payouts | D7: Sachli Zare | I7: 6 | J7: TAZAPAY | K7: Sanat
A8: YOU TECHNOLOGIES GROUP (SINGAPORE) PTE. LTD | B8: APAC | C8: Payouts | D8: XiaoXiao | I8: 7 | J8: SBI REMIT | K8: Sanat
A9: OFX | B9: APAC | C9: Payouts | D9: Hao Nguyen | I9: 8 | J9: MULTIPLIER TECHNOLOGIES PTE LTD | K9: Sanat
A10: EBURY | B10: EUROPE-Non Travel | C10: Payouts | D10: Will Turner | I10: 9 | J10: HIRE BORDERLESS US | K10: Mrinal
A11: MASHREQ | B11: MEA | C11: Payouts | D11: Saikat Roy | I11: 10 | J11: GOLANCE | K11: Sakshi
A12: AL MULLA INTERNATIONAL EXCHANGE COMPANY,K.S.C.C. | B12: MEA | C12: Payouts | D12: Jerome Coelho | I12: 11 | J12: BENDIX EXCHANGE | K12: Mrinal
A13: KASIKORN BANK | B13: APAC | C13: Payouts | D13: Pat Sarisa | I13: 12 | J13: UQPAY PTE LTD PAYOUT | K13: Bhavani
... A99: EIB | B99: MEA | C99: Payouts | D99: Jerome Coelho | I99: 98 | J99: JUST WALLET INC | K99: Mrinal
A100: EPAY LIMITED | B100: APAC | C100: Payouts | D100: Pat Sarisa
A101: EVERPRO HOLDINGS LIMITED | B101: APAC | C101: Payouts | D101: Shared center
A102: EVOCABANK CJSC | B102: MEA | C102: Payouts | D102: Jerome Coelho
A103: EZ MONEY | B103: APAC | C103: Payouts | D103: Shared center
A104: FIFTH AMERICAN CORPORATION O/A REMIT5 | B104: AMERICAS | C104: Payouts | D104: Shared center
A105: TCLUB INC. | B105: AMERICAS | C105: Payouts | D105: Terminated
A106: UNSI US | B106: AMERICAS | C106: Payouts | D106: Unmanaged
A107: Aardua | B107: Americas | C107: Payouts | D107: Terminated
A108: PACIFIC BASIN SHIPPING (HK) LIMITED | B108: APAC | C108: Payouts | D108: Irene
A109: FUTUREPAY GLOBAL | B109: APAC | C109: Payouts | D109: Shared center
A110: GENIEUM | B110: APAC | C110: Payouts | D110: Shared center
A111: GET KOLLO INC. | B111: AMERICAS | C111: Payouts | D111: Lia Susin
... A234: JP Morgan | B234: EUROPE-Non Travel | C234: Verify | D234: Sachli Zare
